Workbook

Sheet 500 Sample
A1: Species | B1: fossorialHabitat | C1: terestrialHabitat | D1: aquaticHabitat | E1: aborealHabitat | F1: bodyLengthMm | G1: clutchSizeMinN | H1: clutchSizeMaxN | I1: directReproduction | J1: larvalReproduction | K1: vivipariousReproduction | L1: habitatType | M1: reproductiveMethod | N1: Check_Body | O1: Check_Min | P1: Check_Max | Q1: Check_Fos | R1: Check_Ter | S1: Check_Aqu | T1: Check_Arb | U1: Check_Dir | V1: Check_Lar | W1: Check_Viv | X1: All_Match | Y1: randID
A2: Eleutherodactylus corona | B2: NA | C2: 1 | D2: NA | E2: 1 | F2: 19.1 | G2: 3 | H2: 3 | I2: 1 | J2: 0 | K2: 0 | L2: =IF( (COUNTIF(B2:E2,"1")+COUNTIF(B2:E2,1))=0, "unknown", MID( IF(OR(B2="1",B2=1)," + fossorial","") & IF(OR(C2="1",C2=1)," + terrestrial","") & IF(OR(D2="1",D2=1)," + aquatic","") & IF(OR(E2="1",E2=1)," + arboreal",""), 4, 999) ) -> terrestrial + arboreal | M2: =IF( AND( (COUNTIF(I2:K2,"1")+COUNTIF(I2:K2,1))=0, (COUNTIF(I2:K2,"0")+COUNTIF(I2:K2,0))=0 ), "unknown", IF( (COUNTIF(I2:K2,"1")+COUNTIF(I2:K2,1))>0, MID( IF(OR(I2=1,I2="1")," + direct","") & IF(OR(J2=1,J2="1")," + larval","") & IF(OR(K2=1,K2="1")," + viviparous",""), 4,999), IF( (COUNTIF(I2:K2,"0")+COUNTIF(I2:K2,0))=3, "none", "unknown") ) ) -> direct | N2: =IFERROR(VALUE(INDEX(rawData!$Z:$Z, MATCH($A2, rawData!$E:$E, 0)))=VALUE($F2),"NA") -> TRUE | O2: =IFERROR(VALUE(INDEX(rawData!$AD:$AD, MATCH($A2, rawData!$E:$E, 0)))=VALUE($G2),"NA") -> TRUE | P2: =IFERROR(VALUE(INDEX(rawData!$AE:$AE, MATCH($A2, rawData!$E:$E, 0)))=VALUE($H2),"NA") -> TRUE | Q2: =IFERROR(INDEX(rawData!$F:$F, MATCH($A2, rawData!$E:$E, 0))=$B2,"NA") -> TRUE | R2: =IFERROR(INDEX(rawData!$G:$G, MATCH($A2, rawData!$E:$E, 0))=$C2,"NA") -> TRUE | S2: =IFERROR(INDEX(rawData!$H:$H, MATCH($A2, rawData!$E:$E, 0))=$D2,"NA") -> TRUE | T2: =IFERROR(INDEX(rawData!$I:$I, MATCH($A2, rawData!$E:$E, 0))=$E2,"NA") -> TRUE | U2: =IFERROR(VALUE(INDEX(rawData!$AI:$AI, MATCH($A2, rawData!$E:$E, 0)))=VALUE($I2),"NA") -> TRUE | V2: =IFERROR(VALUE(INDEX(rawData!$AJ:$AJ, MATCH($A2, rawData!$E:$E, 0)))=VALUE($J2),"NA") -> TRUE | W2: =IFERROR(VALUE(INDEX(rawData!$AK:$AK, MATCH($A2, rawData!$E:$E, 0)))=VALUE($K2),"NA") -> TRUE | X2: =IF(COUNTIF(O2:W2,FALSE)>0,FALSE,TRUE) -> TRUE | Y2: 1
A3: Eurycea quadridigitata | B3: NA | C3: 1 | D3: 1 | E3: NA | F3: 90 | G3: 7 | H3: 62 | I3: 0 | J3: 1 | K3: 0 | L3: =IF( (COUNTIF(B3:E3,"1")+COUNTIF(B3:E3,1))=0, "unknown", MID( IF(OR(B3="1",B3=1)," + fossorial","") & IF(OR(C3="1",C3=1)," + terrestrial","") & IF(OR(D3="1",D3=1)," + aquatic","") & IF(OR(E3="1",E3=1)," + arboreal",""), 4, 999) ) -> terrestrial + aquatic | M3: =IF( AND( (COUNTIF(I3:K3,"1")+COUNTIF(I3:K3,1))=0, (COUNTIF(I3:K3,"0")+COUNTIF(I3:K3,0))=0 ), "unknown", IF( (COUNTIF(I3:K3,"1")+COUNTIF(I3:K3,1))>0, MID( IF(OR(I3=1,I3="1")," + direct","") & IF(OR(J3=1,J3="1")," + larval","") & IF(OR(K3=1,K3="1")," + viviparous",""), 4,999), IF( (COUNTIF(I3:K3,"0")+COUNTIF(I3:K3,0))=3, "none", "unknown") ) ) -> larval | N3: =IFERROR(VALUE(INDEX(rawData!$Z:$Z, MATCH($A3, rawData!$E:$E, 0)))=VALUE($F3),"NA") -> TRUE | O3: =IFERROR(VALUE(INDEX(rawData!$AD:$AD, MATCH($A3, rawData!$E:$E, 0)))=VALUE($G3),"NA") -> TRUE | P3: =IFERROR(VALUE(INDEX(rawData!$AE:$AE, MATCH($A3, rawData!$E:$E, 0)))=VALUE($H3),"NA") -> TRUE | Q3: =IFERROR(INDEX(rawData!$F:$F, MATCH($A3, rawData!$E:$E, 0))=$B3,"NA") -> TRUE | R3: =IFERROR(INDEX(rawData!$G:$G, MATCH($A3, rawData!$E:$E, 0))=$C3,"NA") -> TRUE | S3: =IFERROR(INDEX(rawData!$H:$H, MATCH($A3, rawData!$E:$E, 0))=$D3,"NA") -> TRUE | T3: =IFERROR(INDEX(rawData!$I:$I, MATCH($A3, rawData!$E:$E, 0))=$E3,"NA") -> TRUE | U3: =IFERROR(VALUE(INDEX(rawData!$AI:$AI, MATCH($A3, rawData!$E:$E, 0)))=VALUE($I3),"NA") -> TRUE | V3: =IFERROR(VALUE(INDEX(rawData!$AJ:$AJ, MATCH($A3, rawData!$E:$E, 0)))=VALUE($J3),"NA") -> TRUE | W3: =IFERROR(VALUE(INDEX(rawData!$AK:$AK, MATCH($A3, rawData!$E:$E, 0)))=VALUE($K3),"NA") -> TRUE | X3: =IF(COUNTIF(O3:W3,FALSE)>0,FALSE,TRUE) -> TRUE | Y3: 1
A4: Eleutherodactylus sisyphodemus | B4: NA | C4: 1 | D4: 1 | E4: NA | F4: 18 | G4: 6 | H4: 10 | I4: 1 | J4: 0 | K4: 0 | L4: =IF( (COUNTIF(B4:E4,"1")+COUNTIF(B4:E4,1))=0, "unknown", MID( IF(OR(B4="1",B4=1)," + fossorial","") & IF(OR(C4="1",C4=1)," + terrestrial","") & IF(OR(D4="1",D4=1)," + aquatic","") & IF(OR(E4="1",E4=1)," + arboreal",""), 4, 999) ) -> terrestrial + aquatic | M4: =IF( AND( (COUNTIF(I4:K4,"1")+COUNTIF(I4:K4,1))=0, (COUNTIF(I4:K4,"0")+COUNTIF(I4:K4,0))=0 ), "unknown", IF( (COUNTIF(I4:K4,"1")+COUNTIF(I4:K4,1))>0, MID( IF(OR(I4=1,I4="1")," + direct","") & IF(OR(J4=1,J4="1")," + larval","") & IF(OR(K4=1,K4="1")," + viviparous",""), 4,999), IF( (COUNTIF(I4:K4,"0")+COUNTIF(I4:K4,0))=3, "none", "unknown") ) ) -> direct | N4: =IFERROR(VALUE(INDEX(rawData!$Z:$Z, MATCH($A4, rawData!$E:$E, 0)))=VALUE($F4),"NA") -> TRUE | O4: =IFERROR(VALUE(INDEX(rawData!$AD:$AD, MATCH($A4, rawData!$E:$E, 0)))=VALUE($G4),"NA") -> TRUE | P4: =IFERROR(VALUE(INDEX(rawData!$AE:$AE, MATCH($A4, rawData!$E:$E, 0)))=VALUE($H4),"NA") -> TRUE | Q4: =IFERROR(INDEX(rawData!$F:$F, MATCH($A4, rawData!$E:$E, 0))=$B4,"NA") -> TRUE | R4: =IFERROR(INDEX(rawData!$G:$G, MATCH($A4, rawData!$E:$E, 0))=$C4,"NA") -> TRUE | S4: =IFERROR(INDEX(rawData!$H:$H, MATCH($A4, rawData!$E:$E, 0))=$D4,"NA") -> TRUE | T4: =IFERROR(INDEX(rawData!$I:$I, MATCH($A4, rawData!$E:$E, 0))=$E4,"NA") -> TRUE | U4: =IFERROR(VALUE(INDEX(rawData!$AI:$AI, MATCH($A4, rawData!$E:$E, 0)))=VALUE($I4),"NA") -> TRUE | V4: =IFERROR(VALUE(INDEX(rawData!$AJ:$AJ, MATCH($A4, rawData!$E:$E, 0)))=VALUE($J4),"NA") -> TRUE | W4: =IFERROR(VALUE(INDEX(rawData!$AK:$AK, MATCH($A4, rawData!$E:$E, 0)))=VALUE($K4),"NA") -> TRUE | X4: =IF(COUNTIF(O4:W4,FALSE)>0,FALSE,TRUE) -> TRUE | Y4: 2
A5: Microhyla achatina | B5: NA | C5: 1 | D5: 1 | E5: NA | F5: 25 | G5: 20 | H5: 20 | I5: 0 | J5: 1 | K5: 0 | L5: =IF( (COUNTIF(B5:E5,"1")+COUNTIF(B5:E5,1))=0, "unknown", MID( IF(OR(B5="1",B5=1)," + fossorial","") & IF(OR(C5="1",C5=1)," + terrestrial","") & IF(OR(D5="1",D5=1)," + aquatic","") & IF(OR(E5="1",E5=1)," + arboreal",""), 4, 999) ) -> terrestrial + aquatic | M5: =IF( AND( (COUNTIF(I5:K5,"1")+COUNTIF(I5:K5,1))=0, (COUNTIF(I5:K5,"0")+COUNTIF(I5:K5,0))=0 ), "unknown", IF( (COUNTIF(I5:K5,"1")+COUNTIF(I5:K5,1))>0, MID( IF(OR(I5=1,I5="1")," + direct","") & IF(OR(J5=1,J5="1")," + larval","") & IF(OR(K5=1,K5="1")," + viviparous",""), 4,999), IF( (COUNTIF(I5:K5,"0")+COUNTIF(I5:K5,0))=3, "none", "unknown") ) ) -> larval | N5: =IFERROR(VALUE(INDEX(rawData!$Z:$Z, MATCH($A5, rawData!$E:$E, 0)))=VALUE($F5),"NA") -> TRUE | O5: =IFERROR(VALUE(INDEX(rawData!$AD:$AD, MATCH($A5, rawData!$E:$E, 0)))=VALUE($G5),"NA") -> TRUE | P5: =IFERROR(VALUE(INDEX(rawData!$AE:$AE, MATCH($A5, rawData!$E:$E, 0)))=VALUE($H5),"NA") -> TRUE | Q5: =IFERROR(INDEX(rawData!$F:$F, MATCH($A5, rawData!$E:$E, 0))=$B5,"NA") -> TRUE | R5: =IFERROR(INDEX(rawData!$G:$G, MATCH($A5, rawData!$E:$E, 0))=$C5,"NA") -> TRUE | S5: =IFERROR(INDEX(rawData!$H:$H, MATCH($A5, rawData!$E:$E, 0))=$D5,"NA") -> TRUE | T5: =IFERROR(INDEX(rawData!$I:$I, MATCH($A5, rawData!$E:$E, 0))=$E5,"NA") -> TRUE | U5: =IFERROR(VALUE(INDEX(rawData!$AI:$AI, MATCH($A5, rawData!$E:$E, 0)))=VALUE($I5),"NA") -> TRUE | V5: =IFERROR(VALUE(INDEX(rawData!$AJ:$AJ, MATCH($A5, rawData!$E:$E, 0)))=VALUE($J5),"NA") -> TRUE | W5: =IFERROR(VALUE(INDEX(rawData!$AK:$AK, MATCH($A5, rawData!$E:$E, 0)))=VALUE($K5),"NA") -> TRUE | X5: =IF(COUNTIF(O5:W5,FALSE)>0,FALSE,TRUE) -> TRUE | Y5: 2
A6: Ambystoma barbouri | B6: 1 | C6: 1 | D6: 1 | E6: NA | F6: 168 | G6: 260 | H6: 260 | I6: 0 | J6: 1 | K6: 0 | L6: =IF( (COUNTIF(B6:E6,"1")+COUNTIF(B6:E6,1))=0, "unknown", MID( IF(OR(B6="1",B6=1)," + fossorial","") & IF(OR(C6="1",C6=1)," + terrestrial","") & IF(OR(D6="1",D6=1)," + aquatic","") & IF(OR(E6="1",E6=1)," + arboreal",""), 4, 999) ) -> fossorial + terrestrial + aquatic | M6: =IF( AND( (COUNTIF(I6:K6,"1")+COUNTIF(I6:K6,1))=0, (COUNTIF(I6:K6,"0")+COUNTIF(I6:K6,0))=0 ), "unknown", IF( (COUNTIF(I6:K6,"1")+COUNTIF(I6:K6,1))>0, MID( IF(OR(I6=1,I6="1")," + direct","") & IF(OR(J6=1,J6="1")," + larval","") & IF(OR(K6=1,K6="1")," + viviparous",""), 4,999), IF( (COUNTIF(I6:K6,"0")+COUNTIF(I6:K6,0))=3, "none", "unknown") ) ) -> larval | N6: =IFERROR(VALUE(INDEX(rawData!$Z:$Z, MATCH($A6, rawData!$E:$E, 0)))=VALUE($F6),"NA") -> TRUE | O6: =IFERROR(VALUE(INDEX(rawData!$AD:$AD, MATCH($A6, rawData!$E:$E, 0)))=VALUE($G6),"NA") -> TRUE | P6: =IFERROR(VALUE(INDEX(rawData!$AE:$AE, MATCH($A6, rawData!$E:$E, 0)))=VALUE($H6),"NA") -> TRUE | Q6: =IFERROR(INDEX(rawData!$F:$F, MATCH($A6, rawData!$E:$E, 0))=$B6,"NA") -> TRUE | R6: =IFERROR(INDEX(rawData!$G:$G, MATCH($A6, rawData!$E:$E, 0))=$C6,"NA") -> TRUE | S6: =IFERROR(INDEX(rawData!$H:$H, MATCH($A6, rawData!$E:$E, 0))=$D6,"NA") -> TRUE | T6: =IFERROR(INDEX(rawData!$I:$I, MATCH($A6, rawData!$E:$E, 0))=$E6,"NA") -> TRUE | U6: =IFERROR(VALUE(INDEX(rawData!$AI:$AI, MATCH($A6, rawData!$E:$E, 0)))=VALUE($I6),"NA") -> TRUE | V6: =IFERROR(VALUE(INDEX(rawData!$AJ:$AJ, MATCH($A6, rawData!$E:$E, 0)))=VALUE($J6),"NA") -> TRUE | W6: =IFERROR(VALUE(INDEX(rawData!$AK:$AK, MATCH($A6, rawData!$E:$E, 0)))=VALUE($K6),"NA") -> TRUE | X6: =IF(COUNTIF(O6:W6,FALSE)>0,FALSE,TRUE) -> TRUE | Y6: 2
A7: Smilisca cyanosticta | B7: NA | C7: 1 | D7: 1 | E7: 1 | F7: 70 | G7: 214 | H7: 1844 | I7: 0 | J7: 1 | K7: 0 | L7: =IF( (COUNTIF(B7:E7,"1")+COUNTIF(B7:E7,1))=0, "unknown", MID( IF(OR(B7="1",B7=1)," + fossorial","") & IF(OR(C7="1",C7=1)," + terrestrial","") & IF(OR(D7="1",D7=1)," + aquatic","") & IF(OR(E7="1",E7=1)," + arboreal",""), 4, 999) ) -> terrestrial + aquatic + arboreal | M7: =IF( AND( (COUNTIF(I7:K7,"1")+COUNTIF(I7:K7,1))=0, (COUNTIF(I7:K7,"0")+COUNTIF(I7:K7,0))=0 ), "unknown", IF( (COUNTIF(I7:K7,"1")+COUNTIF(I7:K7,1))>0, MID( IF(OR(I7=1,I7="1")," + direct","") & IF(OR(J7=1,J7="1")," + larval","") & IF(OR(K7=1,K7="1")," + viviparous",""), 4,999), IF( (COUNTIF(I7:K7,"0")+COUNTIF(I7:K7,0))=3, "none", "unknown") ) ) -> larval | N7: =IFERROR(VALUE(INDEX(rawData!$Z:$Z, MATCH($A7, rawData!$E:$E, 0)))=VALUE($F7),"NA") -> TRUE | O7: =IFERROR(VALUE(INDEX(rawData!$AD:$AD, MATCH($A7, rawData!$E:$E, 0)))=VALUE($G7),"NA") -> TRUE | P7: =IFERROR(VALUE(INDEX(rawData!$AE:$AE, MATCH($A7, rawData!$E:$E, 0)))=VALUE($H7),"NA") -> TRUE | Q7: =IFERROR(INDEX(rawData!$F:$F, MATCH($A7, rawData!$E:$E, 0))=$B7,"NA") -> TRUE | R7: =IFERROR(INDEX(rawData!$G:$G, MATCH($A7, rawData!$E:$E, 0))=$C7,"NA") -> TRUE | S7: =IFERROR(INDEX(rawData!$H:$H, MATCH($A7, rawData!$E:$E, 0))=$D7,"NA") -> TRUE | T7: =IFERROR(INDEX(rawData!$I:$I, MATCH($A7, rawData!$E:$E, 0))=$E7,"NA") -> TRUE | U7: =IFERROR(VALUE(INDEX(rawData!$AI:$AI, MATCH($A7, rawData!$E:$E, 0)))=VALUE($I7),"NA") -> TRUE | V7: =IFERROR(VALUE(INDEX(rawData!$AJ:$AJ, MATCH($A7, rawData!$E:$E, 0)))=VALUE($J7),"NA") -> TRUE | W7: =IFERROR(VALUE(INDEX(rawData!$AK:$AK, MATCH($A7, rawData!$E:$E, 0)))=VALUE($K7),"NA") -> TRUE | X7: =IF(COUNTIF(O7:W7,FALSE)>0,FALSE,TRUE) -> TRUE | Y7: 3
A8: Phasmahyla jandaia | B8: NA | C8: 1 | D8: NA | E8: 1 | F8: 32 | G8: 18 | H8: 30 | I8: 0 | J8: 1 | K8: 0 | L8: =IF( (COUNTIF(B8:E8,"1")+COUNTIF(B8:E8,1))=0, "unknown", MID( IF(OR(B8="1",B8=1)," + fossorial","") & IF(OR(C8="1",C8=1)," + terrestrial","") & IF(OR(D8="1",D8=1)," + aquatic","") & IF(OR(E8="1",E8=1)," + arboreal",""), 4, 999) ) -> terrestrial + arboreal | M8: =IF( AND( (COUNTIF(I8:K8,"1")+COUNTIF(I8:K8,1))=0, (COUNTIF(I8:K8,"0")+COUNTIF(I8:K8,0))=0 ), "unknown", IF( (COUNTIF(I8:K8,"1")+COUNTIF(I8:K8,1))>0, MID( IF(OR(I8=1,I8="1")," + direct","") & IF(OR(J8=1,J8="1")," + larval","") & IF(OR(K8=1,K8="1")," + viviparous",""), 4,999), IF( (COUNTIF(I8:K8,"0")+COUNTIF(I8:K8,0))=3, "none", "unknown") ) ) -> larval | N8: =IFERROR(VALUE(INDEX(rawData!$Z:$Z, MATCH($A8, rawData!$E:$E, 0)))=VALUE($F8),"NA") -> TRUE | O8: =IFERROR(VALUE(INDEX(rawData!$AD:$AD, MATCH($A8, rawData!$E:$E, 0)))=VALUE($G8),"NA") -> TRUE | P8: =IFERROR(VALUE(INDEX(rawData!$AE:$AE, MATCH($A8, rawData!$E:$E, 0)))=VALUE($H8),"NA") -> TRUE | Q8: =IFERROR(INDEX(rawData!$F:$F, MATCH($A8, rawData!$E:$E, 0))=$B8,"NA") -> TRUE | R8: =IFERROR(INDEX(rawData!$G:$G, MATCH($A8, rawData!$E:$E, 0))=$C8,"NA") -> TRUE | S8: =IFERROR(INDEX(rawData!$H:$H, MATCH($A8, rawData!$E:$E, 0))=$D8,"NA") -> TRUE | T8: =IFERROR(INDEX(rawData!$I:$I, MATCH($A8, rawData!$E:$E, 0))=$E8,"NA") -> TRUE | U8: =IFERROR(VALUE(INDEX(rawData!$AI:$AI, MATCH($A8, rawData!$E:$E, 0)))=VALUE($I8),"NA") -> TRUE | V8: =IFERROR(VALUE(INDEX(rawData!$AJ:$AJ, MATCH($A8, rawData!$E:$E, 0)))=VALUE($J8),"NA") -> TRUE | W8: =IFERROR(VALUE(INDEX(rawData!$AK:$AK, MATCH($A8, rawData!$E:$E, 0)))=VALUE($K8),"NA") -> TRUE | X8: =IF(COUNTIF(O8:W8,FALSE)>0,FALSE,TRUE) -> TRUE | Y8: 3
A9: Desmognathus welteri | B9: NA | C9: NA | D9: 1 | E9: NA | F9: 122.5 | G9: 18 | H9: 33 | I9: 0 | J9: 1 | K9: 0 | L9: =IF( (COUNTIF(B9:E9,"1")+COUNTIF(B9:E9,1))=0, "unknown", MID( IF(OR(B9="1",B9=1)," + fossorial","") & IF(OR(C9="1",C9=1)," + terrestrial","") & IF(OR(D9="1",D9=1)," + aquatic","") & IF(OR(E9="1",E9=1)," + arboreal",""), 4, 999) ) -> aquatic | M9: =IF( AND( (COUNTIF(I9:K9,"1")+COUNTIF(I9:K9,1))=0, (COUNTIF(I9:K9,"0")+COUNTIF(I9:K9,0))=0 ), "unknown", IF( (COUNTIF(I9:K9,"1")+COUNTIF(I9:K9,1))>0, MID( IF(OR(I9=1,I9="1")," + direct","") & IF(OR(J9=1,J9="1")," + larval","") & IF(OR(K9=1,K9="1")," + viviparous",""), 4,999), IF( (COUNTIF(I9:K9,"0")+COUNTIF(I9:K9,0))=3, "none", "unknown") ) ) -> larval | N9: =IFERROR(VALUE(INDEX(rawData!$Z:$Z, MATCH($A9, rawData!$E:$E, 0)))=VALUE($F9),"NA") -> TRUE | O9: =IFERROR(VALUE(INDEX(rawData!$AD:$AD, MATCH($A9, rawData!$E:$E, 0)))=VALUE($G9),"NA") -> TRUE | P9: =IFERROR(VALUE(INDEX(rawData!$AE:$AE, MATCH($A9, rawData!$E:$E, 0)))=VALUE($H9),"NA") -> TRUE | Q9: =IFERROR(INDEX(rawData!$F:$F, MATCH($A9, rawData!$E:$E, 0))=$B9,"NA") -> TRUE | R9: =IFERROR(INDEX(rawData!$G:$G, MATCH($A9, rawData!$E:$E, 0))=$C9,"NA") -> TRUE | S9: =IFERROR(INDEX(rawData!$H:$H, MATCH($A9, rawData!$E:$E, 0))=$D9,"NA") -> TRUE | T9: =IFERROR(INDEX(rawData!$I:$I, MATCH($A9, rawData!$E:$E, 0))=$E9,"NA") -> TRUE | U9: =IFERROR(VALUE(INDEX(rawData!$AI:$AI, MATCH($A9, rawData!$E:$E, 0)))=VALUE($I9),"NA") -> TRUE | V9: =IFERROR(VALUE(INDEX(rawData!$AJ:$AJ, MATCH($A9, rawData!$E:$E, 0)))=VALUE($J9),"NA") -> TRUE | W9: =IFERROR(VALUE(INDEX(rawData!$AK:$AK, MATCH($A9, rawData!$E:$E, 0)))=VALUE($K9),"NA") -> TRUE | X9: =IF(COUNTIF(O9:W9,FALSE)>0,FALSE,TRUE) -> TRUE | Y9: 4
A10: Smilisca sordida | B10: NA | C10: 1 | D10: 1 | E10: 1 | F10: 64 | G10: 856 | H10: 856 | I10: 0 | J10: 1 | K10: 0 | L10: =IF( (COUNTIF(B10:E10,"1")+COUNTIF(B10:E10,1))=0, "unknown", MID( IF(OR(B10="1",B10=1)," + fossorial","") & IF(OR(C10="1",C10=1)," + terrestrial","") & IF(OR(D10="1",D10=1)," + aquatic","") & IF(OR(E10="1",E10=1)," + arboreal",""), 4, 999) ) -> terrestrial + aquatic + arboreal | M10: =IF( AND( (COUNTIF(I10:K10,"1")+COUNTIF(I10:K10,1))=0, (COUNTIF(I10:K10,"0")+COUNTIF(I10:K10,0))=0 ), "unknown", IF( (COUNTIF(I10:K10,"1")+COUNTIF(I10:K10,1))>0, MID( IF(OR(I10=1,I10="1")," + direct","") & IF(OR(J10=1,J10="1")," + larval","") & IF(OR(K10=1,K10="1")," + viviparous",""), 4,999), IF( (COUNTIF(I10:K10,"0")+COUNTIF(I10:K10,0))=3, "none", "unknown") ) ) -> larval | N10: =IFERROR(VALUE(INDEX(rawData!$Z:$Z, MATCH($A10, rawData!$E:$E, 0)))=VALUE($F10),"NA") -> TRUE | O10: =IFERROR(VALUE(INDEX(rawData!$AD:$AD, MATCH($A10, rawData!$E:$E, 0)))=VALUE($G10),"NA") -> TRUE | P10: =IFERROR(VALUE(INDEX(rawData!$AE:$AE, MATCH($A10, rawData!$E:$E, 0)))=VALUE($H10),"NA") -> TRUE | Q10: =IFERROR(INDEX(rawData!$F:$F, MATCH($A10, rawData!$E:$E, 0))=$B10,"NA") -> TRUE | R10: =IFERROR(INDEX(rawData!$G:$G, MATCH($A10, rawData!$E:$E, 0))=$C10,"NA") -> TRUE | S10: =IFERROR(INDEX(rawData!$H:$H, MATCH($A10, rawData!$E:$E, 0))=$D10,"NA") -> TRUE | T10: =IFERROR(INDEX(rawData!$I:$I, MATCH($A10, rawData!$E:$E, 0))=$E10,"NA") -> TRUE | U10: =IFERROR(VALUE(INDEX(rawData!$AI:$AI, MATCH($A10, rawData!$E:$E, 0)))=VALUE($I10),"NA") -> TRUE | V10: =IFERROR(VALUE(INDEX(rawData!$AJ:$AJ, MATCH($A10, rawData!$E:$E, 0)))=VALUE($J10),"NA") -> TRUE | W10: =IFERROR(VALUE(INDEX(rawData!$AK:$AK, MATCH($A10, rawData!$E:$E, 0)))=VALUE($K10),"NA") -> TRUE | X10: =IF(COUNTIF(O10:W10,FALSE)>0,FALSE,TRUE) -> TRUE | Y10: 8
A11: Physalaemus maculiventris | B11: NA | C11: 1 | D11: 1 | E11: NA | F11: 25 | G11: 129 | H11: 129 | I11: 0 | J11: 1 | K11: 0 | L11: =IF( (COUNTIF(B11:E11,"1")+COUNTIF(B11:E11,1))=0, "unknown", MID( IF(OR(B11="1",B11=1)," + fossorial","") & IF(OR(C11="1",C11=1)," + terrestrial","") & IF(OR(D11="1",D11=1)," + aquatic","") & IF(OR(E11="1",E11=1)," + arboreal",""), 4, 999) ) -> terrestrial + aquatic | M11: =IF( AND( (COUNTIF(I11:K11,"1")+COUNTIF(I11:K11,1))=0, (COUNTIF(I11:K11,"0")+COUNTIF(I11:K11,0))=0 ), "unknown", IF( (COUNTIF(I11:K11,"1")+COUNTIF(I11:K11,1))>0, MID( IF(OR(I11=1,I11="1")," + direct","") & IF(OR(J11=1,J11="1")," + larval","") & IF(OR(K11=1,K11="1")," + viviparous",""), 4,999), IF( (COUNTIF(I11:K11,"0")+COUNTIF(I11:K11,0))=3, "none", "unknown") ) ) -> larval | N11: =IFERROR(VALUE(INDEX(rawData!$Z:$Z, MATCH($A11, rawData!$E:$E, 0)))=VALUE($F11),"NA") -> TRUE | O11: =IFERROR(VALUE(INDEX(rawData!$AD:$AD, MATCH($A11, rawData!$E:$E, 0)))=VALUE($G11),"NA") -> TRUE | P11: =IFERROR(VALUE(INDEX(rawData!$AE:$AE, MATCH($A11, rawData!$E:$E, 0)))=VALUE($H11),"NA") -> TRUE | Q11: =IFERROR(INDEX(rawData!$F:$F, MATCH($A11, rawData!$E:$E, 0))=$B11,"NA") -> TRUE | R11: =IFERROR(INDEX(rawData!$G:$G, MATCH($A11, rawData!$E:$E, 0))=$C11,"NA") -> TRUE | S11: =IFERROR(INDEX(rawData!$H:$H, MATCH($A11, rawData!$E:$E, 0))=$D11,"NA") -> TRUE | T11: =IFERROR(INDEX(rawData!$I:$I, MATCH($A11, rawData!$E:$E, 0))=$E11,"NA") -> TRUE | U11: =IFERROR(VALUE(INDEX(rawData!$AI:$AI, MATCH($A11, rawData!$E:$E, 0)))=VALUE($I11),"NA") -> TRUE | V11: =IFERROR(VALUE(INDEX(rawData!$AJ:$AJ, MATCH($A11, rawData!$E:$E, 0)))=VALUE($J11),"NA") -> TRUE | W11: =IFERROR(VALUE(INDEX(rawData!$AK:$AK, MATCH($A11, rawData!$E:$E, 0)))=VALUE($K11),"NA") -> TRUE | X11: =IF(COUNTIF(O11:W11,FALSE)>0,FALSE,TRUE) -> TRUE | Y11: 9
A12: Allophryne ruthveni | B12: NA | C12: 1 | D12: 1 | E12: 1 | F12: 31 | G12: 300 | H12: 300 | I12: 0 | J12: 1 | K12: 0 | L12: =IF( (COUNTIF(B12:E12,"1")+COUNTIF(B12:E12,1))=0, "unknown", MID( IF(OR(B12="1",B12=1)," + fossorial","") & IF(OR(C12="1",C12=1)," + terrestrial","") & IF(OR(D12="1",D12=1)," + aquatic","") & IF(OR(E12="1",E12=1)," + arboreal",""), 4, 999) ) -> terrestrial + aquatic + arboreal | M12: =IF( AND( (COUNTIF(I12:K12,"1")+COUNTIF(I12:K12,1))=0, (COUNTIF(I12:K12,"0")+COUNTIF(I12:K12,0))=0 ), "unknown", IF( (COUNTIF(I12:K12,"1")+COUNTIF(I12:K12,1))>0, MID( IF(OR(I12=1,I12="1")," + direct","") & IF(OR(J12=1,J12="1")," + larval","") & IF(OR(K12=1,K12="1")," + viviparous",""), 4,999), IF( (COUNTIF(I12:K12,"0")+COUNTIF(I12:K12,0))=3, "none", "unknown") ) ) -> larval | N12: =IFERROR(VALUE(INDEX(rawData!$Z:$Z, MATCH($A12, rawData!$E:$E, 0)))=VALUE($F12),"NA") -> TRUE | O12: =IFERROR(VALUE(INDEX(rawData!$AD:$AD, MATCH($A12, rawData!$E:$E, 0)))=VALUE($G12),"NA") -> TRUE | P12: =IFERROR(VALUE(INDEX(rawData!$AE:$AE, MATCH($A12, rawData!$E:$E, 0)))=VALUE($H12),"NA") -> TRUE | Q12: =IFERROR(INDEX(rawData!$F:$F, MATCH($A12, rawData!$E:$E, 0))=$B12,"NA") -> TRUE | R12: =IFERROR(INDEX(rawData!$G:$G, MATCH($A12, rawData!$E:$E, 0))=$C12,"NA") -> TRUE | S12: =IFERROR(INDEX(rawData!$H:$H, MATCH($A12, rawData!$E:$E, 0))=$D12,"NA") -> TRUE | T12: =IFERROR(INDEX(rawData!$I:$I, MATCH($A12, rawData!$E:$E, 0))=$E12,"NA") -> TRUE | U12: =IFERROR(VALUE(INDEX(rawData!$AI:$AI, MATCH($A12, rawData!$E:$E, 0)))=VALUE($I12),"NA") -> TRUE | V12: =IFERROR(VALUE(INDEX(rawData!$AJ:$AJ, MATCH($A12, rawData!$E:$E, 0)))=VALUE($J12),"NA") -> TRUE | W12: =IFERROR(VALUE(INDEX(rawData!$AK:$AK, MATCH($A12, rawData!$E:$E, 0)))=VALUE($K12),"NA") -> TRUE | X12: =IF(COUNTIF(O12:W12,FALSE)>0,FALSE,TRUE) -> TRUE | Y12: 11
A13: Gegeneophis ramaswamii | B13: 1 | C13: 1 | D13: 1 | E13: NA | F13: 340 | G13: 2 | H13: 21 | I13: 1 | J13: 0 | K13: 0 | L13: =IF( (COUNTIF(B13:E13,"1")+COUNTIF(B13:E13,1))=0, "unknown", MID( IF(OR(B13="1",B13=1)," + fossorial","") & IF(OR(C13="1",C13=1)," + terrestrial","") & IF(OR(D13="1",D13=1)," + aquatic","") & IF(OR(E13="1",E13=1)," + arboreal",""), 4, 999) ) -> fossorial + terrestrial + aquatic | M13: =IF( AND( (COUNTIF(I13:K13,"1")+COUNTIF(I13:K13,1))=0, (COUNTIF(I13:K13,"0")+COUNTIF(I13:K13,0))=0 ), "unknown", IF( (COUNTIF(I13:K13,"1")+COUNTIF(I13:K13,1))>0, MID( IF(OR(I13=1,I13="1")," + direct","") & IF(OR(J13=1,J13="1")," + larval","") & IF(OR(K13=1,K13="1")," + viviparous",""), 4,999), IF( (COUNTIF(I13:K13,"0")+COUNTIF(I13:K13,0))=3, "none", "unknown") ) ) -> direct | N13: =IFERROR(VALUE(INDEX(rawData!$Z:$Z, MATCH($A13, rawData!$E:$E, 0)))=VALUE($F13),"NA") -> TRUE | O13: =IFERROR(VALUE(INDEX(rawData!$AD:$AD, MATCH($A13, rawData!$E:$E, 0)))=VALUE($G13),"NA") -> TRUE | P13: =IFERROR(VALUE(INDEX(rawData!$AE:$AE, MATCH($A13, rawData!$E:$E, 0)))=VALUE($H13),"NA") -> TRUE | Q13: =IFERROR(INDEX(rawData!$F:$F, MATCH($A13, rawData!$E:$E, 0))=$B13,"NA") -> TRUE | R13: =IFERROR(INDEX(rawData!$G:$G, MATCH($A13, rawData!$E:$E, 0))=$C13,"NA") -> TRUE | S13: =IFERROR(INDEX(rawData!$H:$H, MATCH($A13, rawData!$E:$E, 0))=$D13,"NA") -> TRUE | T13: =IFERROR(INDEX(rawData!$I:$I, MATCH($A13, rawData!$E:$E, 0))=$E13,"NA") -> TRUE | U13: =IFERROR(VALUE(INDEX(rawData!$AI:$AI, MATCH($A13, rawData!$E:$E, 0)))=VALUE($I13),"NA") -> TRUE | V13: =IFERROR(VALUE(INDEX(rawData!$AJ:$AJ, MATCH($A13, rawData!$E:$E, 0)))=VALUE($J13),"NA") -> TRUE | W13: =IFERROR(VALUE(INDEX(rawData!$AK:$AK, MATCH($A13, rawData!$E:$E, 0)))=VALUE($K13),"NA") -> TRUE | X13: =IF(COUNTIF(O13:W13,FALSE)>0,FALSE,TRUE) -> TRUE | Y13: 11
A14: Litoria longipes | B14: 1 | C14: 1 | D14: NA | E14: NA | F14: 45 | G14: 50 | H14: 2000 | I14: 0 | J14: 1 | K14: 0 | L14: =IF( (COUNTIF(B14:E14,"1")+COUNTIF(B14:E14,1))=0, "unknown", MID( IF(OR(B14="1",B14=1)," + fossorial","") & IF(OR(C14="1",C14=1)," + terrestrial","") & IF(OR(D14="1",D14=1)," + aquatic","") & IF(OR(E14="1",E14=1)," + arboreal",""), 4, 999) ) -> fossorial + terrestrial | M14: =IF( AND( (COUNTIF(I14:K14,"1")+COUNTIF(I14:K14,1))=0, (COUNTIF(I14:K14,"0")+COUNTIF(I14:K14,0))=0 ), "unknown", IF( (COUNTIF(I14:K14,"1")+COUNTIF(I14:K14,1))>0, MID( IF(OR(I14=1,I14="1")," + direct","") & IF(OR(J14=1,J14="1")," + larval","") & IF(OR(K14=1,K14="1")," + viviparous",""), 4,999), IF( (COUNTIF(I14:K14,"0")+COUNTIF(I14:K14,0))=3, "none", "unknown") ) ) -> larval | N14: =IFERROR(VALUE(INDEX(rawData!$Z:$Z, MATCH($A14, rawData!$E:$E, 0)))=VALUE($F14),"NA") -> TRUE | O14: =IFERROR(VALUE(INDEX(rawData!$AD:$AD, MATCH($A14, rawData!$E:$E, 0)))=VALUE($G14),"NA") -> TRUE | P14: =IFERROR(VALUE(INDEX(rawData!$AE:$AE, MATCH($A14, rawData!$E:$E, 0)))=VALUE($H14),"NA") -> TRUE | Q14: =IFERROR(INDEX(rawData!$F:$F, MATCH($A14, rawData!$E:$E, 0))=$B14,"NA") -> TRUE | R14: =IFERROR(INDEX(rawData!$G:$G, MATCH($A14, rawData!$E:$E, 0))=$C14,"NA") -> TRUE | S14: =IFERROR(INDEX(rawData!$H:$H, MATCH($A14, rawData!$E:$E, 0))=$D14,"NA") -> TRUE | T14: =IFERROR(INDEX(rawData!$I:$I, MATCH($A14, rawData!$E:$E, 0))=$E14,"NA") -> TRUE | U14: =IFERROR(VALUE(INDEX(rawData!$AI:$AI, MATCH($A14, rawData!$E:$E, 0)))=VALUE($I14),"NA") -> TRUE | V14: =IFERROR(VALUE(INDEX(rawData!$AJ:$AJ, MATCH($A14, rawData!$E:$E, 0)))=VALUE($J14),"NA") -> TRUE | W14: =IFERROR(VALUE(INDEX(rawData!$AK:$AK, MATCH($A14, rawData!$E:$E, 0)))=VALUE($K14),"NA") -> TRUE | X14: =IF(COUNTIF(O14:W14,FALSE)>0,FALSE,TRUE) -> TRUE | Y14: 12
A15: Hyla plicata | B15: NA | C15: 1 | D15: NA | E15: 1 | F15: 47.4 | G15: 265 | H15: 265 | I15: 0 | J15: 1 | K15: 0 | L15: =IF( (COUNTIF(B15:E15,"1")+COUNTIF(B15:E15,1))=0, "unknown", MID( IF(OR(B15="1",B15=1)," + fossorial","") & IF(OR(C15="1",C15=1)," + terrestrial","") & IF(OR(D15="1",D15=1)," + aquatic","") & IF(OR(E15="1",E15=1)," + arboreal",""), 4, 999) ) -> terrestrial + arboreal | M15: =IF( AND( (COUNTIF(I15:K15,"1")+COUNTIF(I15:K15,1))=0, (COUNTIF(I15:K15,"0")+COUNTIF(I15:K15,0))=0 ), "unknown", IF( (COUNTIF(I15:K15,"1")+COUNTIF(I15:K15,1))>0, MID( IF(OR(I15=1,I15="1")," + direct","") & IF(OR(J15=1,J15="1")," + larval","") & IF(OR(K15=1,K15="1")," + viviparous",""), 4,999), IF( (COUNTIF(I15:K15,"0")+COUNTIF(I15:K15,0))=3, "none", "unknown") ) ) -> larval | N15: =IFERROR(VALUE(INDEX(rawData!$Z:$Z, MATCH($A15, rawData!$E:$E, 0)))=VALUE($F15),"NA") -> TRUE | O15: =IFERROR(VALUE(INDEX(rawData!$AD:$AD, MATCH($A15, rawData!$E:$E, 0)))=VALUE($G15),"NA") -> TRUE | P15: =IFERROR(VALUE(INDEX(rawData!$AE:$AE, MATCH($A15, rawData!$E:$E, 0)))=VALUE($H15),"NA") -> TRUE | Q15: =IFERROR(INDEX(rawData!$F:$F, MATCH($A15, rawData!$E:$E, 0))=$B15,"NA") -> TRUE | R15: =IFERROR(INDEX(rawData!$G:$G, MATCH($A15, rawData!$E:$E, 0))=$C15,"NA") -> TRUE | S15: =IFERROR(INDEX(rawData!$H:$H, MATCH($A15, rawData!$E:$E, 0))=$D15,"NA") -> TRUE | T15: =IFERROR(INDEX(rawData!$I:$I, MATCH($A15, rawData!$E:$E, 0))=$E15,"NA") -> TRUE | U15: =IFERROR(VALUE(INDEX(rawData!$AI:$AI, MATCH($A15, rawData!$E:$E, 0)))=VALUE($I15),"NA") -> TRUE | V15: =IFERROR(VALUE(INDEX(rawData!$AJ:$AJ, MATCH($A15, rawData!$E:$E, 0)))=VALUE($J15),"NA") -> TRUE | W15: =IFERROR(VALUE(INDEX(rawData!$AK:$AK, MATCH($A15, rawData!$E:$E, 0)))=VALUE($K15),"NA") -> TRUE | X15: =IF(COUNTIF(O15:W15,FALSE)>0,FALSE,TRUE) -> TRUE | Y15: 13
A16: Scutiger mammatus | B16: NA | C16: 1 | D16: 1 | E16: 1 | F16: 70.5 | G16: 436 | H16: 606 | I16: 0 | J16: 1 | K16: 0 | L16: =IF( (COUNTIF(B16:E16,"1")+COUNTIF(B16:E16,1))=0, "unknown", MID( IF(OR(B16="1",B16=1)," + fossorial","") & IF(OR(C16="1",C16=1)," + terrestrial","") & IF(OR(D16="1",D16=1)," + aquatic","") & IF(OR(E16="1",E16=1)," + arboreal",""), 4, 999) ) -> terrestrial + aquatic + arboreal | M16: =IF( AND( (COUNTIF(I16:K16,"1")+COUNTIF(I16:K16,1))=0, (COUNTIF(I16:K16,"0")+COUNTIF(I16:K16,0))=0 ), "unknown", IF( (COUNTIF(I16:K16,"1")+COUNTIF(I16:K16,1))>0, MID( IF(OR(I16=1,I16="1")," + direct","") & IF(OR(J16=1,J16="1")," + larval","") & IF(OR(K16=1,K16="1")," + viviparous",""), 4,999), IF( (COUNTIF(I16:K16,"0")+COUNTIF(I16:K16,0))=3, "none", "unknown") ) ) -> larval | N16: =IFERROR(VALUE(INDEX(rawData!$Z:$Z, MATCH($A16, rawData!$E:$E, 0)))=VALUE($F16),"NA") -> TRUE | O16: =IFERROR(VALUE(INDEX(rawData!$AD:$AD, MATCH($A16, rawData!$E:$E, 0)))=VALUE($G16),"NA") -> TRUE | P16: =IFERROR(VALUE(INDEX(rawData!$AE:$AE, MATCH($A16, rawData!$E:$E, 0)))=VALUE($H16),"NA") -> TRUE | Q16: =IFERROR(INDEX(rawData!$F:$F, MATCH($A16, rawData!$E:$E, 0))=$B16,"NA") -> TRUE | R16: =IFERROR(INDEX(rawData!$G:$G, MATCH($A16, rawData!$E:$E, 0))=$C16,"NA") -> TRUE | S16: =IFERROR(INDEX(rawData!$H:$H, MATCH($A16, rawData!$E:$E, 0))=$D16,"NA") -> TRUE | T16: =IFERROR(INDEX(rawData!$I:$I, MATCH($A16, rawData!$E:$E, 0))=$E16,"NA") -> TRUE | U16: =IFERROR(VALUE(INDEX(rawData!$AI:$AI, MATCH($A16, rawData!$E:$E, 0)))=VALUE($I16),"NA") -> TRUE | V16: =IFERROR(VALUE(INDEX(rawData!$AJ:$AJ, MATCH($A16, rawData!$E:$E, 0)))=VALUE($J16),"NA") -> TRUE | W16: =IFERROR(VALUE(INDEX(rawData!$AK:$AK, MATCH($A16, rawData!$E:$E, 0)))=VALUE($K16),"NA") -> TRUE | X16: =IF(COUNTIF(O16:W16,FALSE)>0,FALSE,TRUE) -> TRUE | Y16: 14
A17: Bufo tibetanus | B17: NA | C17: 1 | D17: 1 | E17: NA | F17: 72.2 | G17: 4000 | H17: 4000 | I17: 0 | J17: 1 | K17: 0 | L17: =IF( (COUNTIF(B17:E17,"1")+COUNTIF(B17:E17,1))=0, "unknown", MID( IF(OR(B17="1",B17=1)," + fossorial","") & IF(OR(C17="1",C17=1)," + terrestrial","") & IF(OR(D17="1",D17=1)," + aquatic","") & IF(OR(E17="1",E17=1)," + arboreal",""), 4, 999) ) -> terrestrial + aquatic | M17: =IF( AND( (COUNTIF(I17:K17,"1")+COUNTIF(I17:K17,1))=0, (COUNTIF(I17:K17,"0")+COUNTIF(I17:K17,0))=0 ), "unknown", IF( (COUNTIF(I17:K17,"1")+COUNTIF(I17:K17,1))>0, MID( IF(OR(I17=1,I17="1")," + direct","") & IF(OR(J17=1,J17="1")," + larval","") & IF(OR(K17=1,K17="1")," + viviparous",""), 4,999), IF( (COUNTIF(I17:K17,"0")+COUNTIF(I17:K17,0))=3, "none", "unknown") ) ) -> larval | N17: =IFERROR(VALUE(INDEX(rawData!$Z:$Z, MATCH($A17, rawData!$E:$E, 0)))=VALUE($F17),"NA") -> TRUE | O17: =IFERROR(VALUE(INDEX(rawData!$AD:$AD, MATCH($A17, rawData!$E:$E, 0)))=VALUE($G17),"NA") -> TRUE | P17: =IFERROR(VALUE(INDEX(rawData!$AE:$AE, MATCH($A17, rawData!$E:$E, 0)))=VALUE($H17),"NA") -> TRUE | Q17: =IFERROR(INDEX(rawData!$F:$F, MATCH($A17, rawData!$E:$E, 0))=$B17,"NA") -> TRUE | R17: =IFERROR(INDEX(rawData!$G:$G, MATCH($A17, rawData!$E:$E, 0))=$C17,"NA") -> TRUE | S17: =IFERROR(INDEX(rawData!$H:$H, MATCH($A17, rawData!$E:$E, 0))=$D17,"NA") -> TRUE | T17: =IFERROR(INDEX(rawData!$I:$I, MATCH($A17, rawData!$E:$E, 0))=$E17,"NA") -> TRUE | U17: =IFERROR(VALUE(INDEX(rawData!$AI:$AI, MATCH($A17, rawData!$E:$E, 0)))=VALUE($I17),"NA") -> TRUE | V17: =IFERROR(VALUE(INDEX(rawData!$AJ:$AJ, MATCH($A17, rawData!$E:$E, 0)))=VALUE($J17),"NA") -> TRUE | W17: =IFERROR(VALUE(INDEX(rawData!$AK:$AK, MATCH($A17, rawData!$E:$E, 0)))=VALUE($K17),"NA") -> TRUE | X17: =IF(COUNTIF(O17:W17,FALSE)>0,FALSE,TRUE) -> TRUE | Y17: 15
A18: Nymphargus griffithsi | B18: NA | C18: 1 | D18: NA | E18: 1 | F18: 26.6 | G18: 9 | H18: 9 | I18: 0 | J18: 1 | K18: 0 | L18: =IF( (COUNTIF(B18:E18,"1")+COUNTIF(B18:E18,1))=0, "unknown", MID( IF(OR(B18="1",B18=1)," + fossorial","") & IF(OR(C18="1",C18=1)," + terrestrial","") & IF(OR(D18="1",D18=1)," + aquatic","") & IF(OR(E18="1",E18=1)," + arboreal",""), 4, 999) ) -> terrestrial + arboreal | M18: =IF( AND( (COUNTIF(I18:K18,"1")+COUNTIF(I18:K18,1))=0, (COUNTIF(I18:K18,"0")+COUNTIF(I18:K18,0))=0 ), "unknown", IF( (COUNTIF(I18:K18,"1")+COUNTIF(I18:K18,1))>0, MID( IF(OR(I18=1,I18="1")," + direct","") & IF(OR(J18=1,J18="1")," + larval","") & IF(OR(K18=1,K18="1")," + viviparous",""), 4,999), IF( (COUNTIF(I18:K18,"0")+COUNTIF(I18:K18,0))=3, "none", "unknown") ) ) -> larval | N18: =IFERROR(VALUE(INDEX(rawData!$Z:$Z, MATCH($A18, rawData!$E:$E, 0)))=VALUE($F18),"NA") -> TRUE | O18: =IFERROR(VALUE(INDEX(rawData!$AD:$AD, MATCH($A18, rawData!$E:$E, 0)))=VALUE($G18),"NA") -> TRUE | P18: =IFERROR(VALUE(INDEX(rawData!$AE:$AE, MATCH($A18, rawData!$E:$E, 0)))=VALUE($H18),"NA") -> TRUE | Q18: =IFERROR(INDEX(rawData!$F:$F, MATCH($A18, rawData!$E:$E, 0))=$B18,"NA") -> TRUE | R18: =IFERROR(INDEX(rawData!$G:$G, MATCH($A18, rawData!$E:$E, 0))=$C18,"NA") -> TRUE | S18: =IFERROR(INDEX(rawData!$H:$H, MATCH($A18, rawData!$E:$E, 0))=$D18,"NA") -> TRUE | T18: =IFERROR(INDEX(rawData!$I:$I, MATCH($A18, rawData!$E:$E, 0))=$E18,"NA") -> TRUE | U18: =IFERROR(VALUE(INDEX(rawData!$AI:$AI, MATCH($A18, rawData!$E:$E, 0)))=VALUE($I18),"NA") -> TRUE | V18: =IFERROR(VALUE(INDEX(rawData!$AJ:$AJ, MATCH($A18, rawData!$E:$E, 0)))=VALUE($J18),"NA") -> TRUE | W18: =IFERROR(VALUE(INDEX(rawData!$AK:$AK, MATCH($A18, rawData!$E:$E, 0)))=VALUE($K18),"NA") -> TRUE | X18: =IF(COUNTIF(O18:W18,FALSE)>0,FALSE,TRUE) -> TRUE | Y18: 19
A19: Pelophylax cerigensis | B19: NA | C19: 1 | D19: 1 | E19: NA | F19: 70 | G19: 15000 | H19: 15000 | I19: 0 | J19: 1 | K19: 0 | L19: =IF( (COUNTIF(B19:E19,"1")+COUNTIF(B19:E19,1))=0, "unknown", MID( IF(OR(B19="1",B19=1)," + fossorial","") & IF(OR(C19="1",C19=1)," + terrestrial","") & IF(OR(D19="1",D19=1)," + aquatic","") & IF(OR(E19="1",E19=1)," + arboreal",""), 4, 999) ) -> terrestrial + aquatic | M19: =IF( AND( (COUNTIF(I19:K19,"1")+COUNTIF(I19:K19,1))=0, (COUNTIF(I19:K19,"0")+COUNTIF(I19:K19,0))=0 ), "unknown", IF( (COUNTIF(I19:K19,"1")+COUNTIF(I19:K19,1))>0, MID( IF(OR(I19=1,I19="1")," + direct","") & IF(OR(J19=1,J19="1")," + larval","") & IF(OR(K19=1,K19="1")," + viviparous",""), 4,999), IF( (COUNTIF(I19:K19,"0")+COUNTIF(I19:K19,0))=3, "none", "unknown") ) ) -> larval | N19: =IFERROR(VALUE(INDEX(rawData!$Z:$Z, MATCH($A19, rawData!$E:$E, 0)))=VALUE($F19),"NA") -> TRUE | O19: =IFERROR(VALUE(INDEX(rawData!$AD:$AD, MATCH($A19, rawData!$E:$E, 0)))=VALUE($G19),"NA") -> TRUE | P19: =IFERROR(VALUE(INDEX(rawData!$AE:$AE, MATCH($A19, rawData!$E:$E, 0)))=VALUE($H19),"NA") -> TRUE | Q19: =IFERROR(INDEX(rawData!$F:$F, MATCH($A19, rawData!$E:$E, 0))=$B19,"NA") -> TRUE | R19: =IFERROR(INDEX(rawData!$G:$G, MATCH($A19, rawData!$E:$E, 0))=$C19,"NA") -> TRUE | S19: =IFERROR(INDEX(rawData!$H:$H, MATCH($A19, rawData!$E:$E, 0))=$D19,"NA") -> TRUE | T19: =IFERROR(INDEX(rawData!$I:$I, MATCH($A19, rawData!$E:$E, 0))=$E19,"NA") -> TRUE | U19: =IFERROR(VALUE(INDEX(rawData!$AI:$AI, MATCH($A19, rawData!$E:$E, 0)))=VALUE($I19),"NA") -> TRUE | V19: =IFERROR(VALUE(INDEX(rawData!$AJ:$AJ, MATCH($A19, rawData!$E:$E, 0)))=VALUE($J19),"NA") -> TRUE | W19: =IFERROR(VALUE(INDEX(rawData!$AK:$AK, MATCH($A19, rawData!$E:$E, 0)))=VALUE($K19),"NA") -> TRUE | X19: =IF(COUNTIF(O19:W19,FALSE)>0,FALSE,TRUE) -> TRUE | Y19: 20
A20: Fejervarya cancrivora | B20: NA | C20: 1 | D20: 1 | E20: 1 | F20: 113 | G20: 90 | H20: 1187 | I20: 0 | J20: 1 | K20: 0 | L20: =IF( (COUNTIF(B20:E20,"1")+COUNTIF(B20:E20,1))=0, "unknown", MID( IF(OR(B20="1",B20=1)," + fossorial","") & IF(OR(C20="1",C20=1)," + terrestrial","") & IF(OR(D20="1",D20=1)," + aquatic","") & IF(OR(E20="1",E20=1)," + arboreal",""), 4, 999) ) -> terrestrial + aquatic + arboreal | M20: =IF( AND( (COUNTIF(I20:K20,"1")+COUNTIF(I20:K20,1))=0, (COUNTIF(I20:K20,"0")+COUNTIF(I20:K20,0))=0 ), "unknown", IF( (COUNTIF(I20:K20,"1")+COUNTIF(I20:K20,1))>0, MID( IF(OR(I20=1,I20="1")," + direct","") & IF(OR(J20=1,J20="1")," + larval","") & IF(OR(K20=1,K20="1")," + viviparous",""), 4,999), IF( (COUNTIF(I20:K20,"0")+COUNTIF(I20:K20,0))=3, "none", "unknown") ) ) -> larval | N20: =IFERROR(VALUE(INDEX(rawData!$Z:$Z, MATCH($A20, rawData!$E:$E, 0)))=VALUE($F20),"NA") -> TRUE | O20: =IFERROR(VALUE(INDEX(rawData!$AD:$AD, MATCH($A20, rawData!$E:$E, 0)))=VALUE($G20),"NA") -> TRUE | P20: =IFERROR(VALUE(INDEX(rawData!$AE:$AE, MATCH($A20, rawData!$E:$E, 0)))=VALUE($H20),"NA") -> TRUE | Q20: =IFERROR(INDEX(rawData!$F:$F, MATCH($A20, rawData!$E:$E, 0))=$B20,"NA") -> TRUE | R20: =IFERROR(INDEX(rawData!$G:$G, MATCH($A20, rawData!$E:$E, 0))=$C20,"NA") -> TRUE | S20: =IFERROR(INDEX(rawData!$H:$H, MATCH($A20, rawData!$E:$E, 0))=$D20,"NA") -> TRUE | T20: =IFERROR(INDEX(rawData!$I:$I, MATCH($A20, rawData!$E:$E, 0))=$E20,"NA") -> TRUE | U20: =IFERROR(VALUE(INDEX(rawData!$AI:$AI, MATCH($A20, rawData!$E:$E, 0)))=VALUE($I20),"NA") -> TRUE | V20: =IFERROR(VALUE(INDEX(rawData!$AJ:$AJ, MATCH($A20, rawData!$E:$E, 0)))=VALUE($J20),"NA") -> TRUE | W20: =IFERROR(VALUE(INDEX(rawData!$AK:$AK, MATCH($A20, rawData!$E:$E, 0)))=VALUE($K20),"NA") -> TRUE | X20: =IF(COUNTIF(O20:W20,FALSE)>0,FALSE,TRUE) -> TRUE | Y20: 22
A21: Litoria gracilenta | B21: NA | C21: 1 | D21: 1 | E21: 1 | F21: 45 | G21: 400 | H21: 1100 | I21: 0 | J21: 1 | K21: 0 | L21: =IF( (COUNTIF(B21:E21,"1")+COUNTIF(B21:E21,1))=0, "unknown", MID( IF(OR(B21="1",B21=1)," + fossorial","") & IF(OR(C21="1",C21=1)," + terrestrial","") & IF(OR(D21="1",D21=1)," + aquatic","") & IF(OR(E21="1",E21=1)," + arboreal",""), 4, 999) ) -> terrestrial + aquatic + arboreal | M21: =IF( AND( (COUNTIF(I21:K21,"1")+COUNTIF(I21:K21,1))=0, (COUNTIF(I21:K21,"0")+COUNTIF(I21:K21,0))=0 ), "unknown", IF( (COUNTIF(I21:K21,"1")+COUNTIF(I21:K21,1))>0, MID( IF(OR(I21=1,I21="1")," + direct","") & IF(OR(J21=1,J21="1")," + larval","") & IF(OR(K21=1,K21="1")," + viviparous",""), 4,999), IF( (COUNTIF(I21:K21,"0")+COUNTIF(I21:K21,0))=3, "none", "unknown") ) ) -> larval | N21: =IFERROR(VALUE(INDEX(rawData!$Z:$Z, MATCH($A21, rawData!$E:$E, 0)))=VALUE($F21),"NA") -> TRUE | O21: =IFERROR(VALUE(INDEX(rawData!$AD:$AD, MATCH($A21, rawData!$E:$E, 0)))=VALUE($G21),"NA") -> TRUE | P21: =IFERROR(VALUE(INDEX(rawData!$AE:$AE, MATCH($A21, rawData!$E:$E, 0)))=VALUE($H21),"NA") -> TRUE | Q21: =IFERROR(INDEX(rawData!$F:$F, MATCH($A21, rawData!$E:$E, 0))=$B21,"NA") -> TRUE | R21: =IFERROR(INDEX(rawData!$G:$G, MATCH($A21, rawData!$E:$E, 0))=$C21,"NA") -> TRUE | S21: =IFERROR(INDEX(rawData!$H:$H, MATCH($A21, rawData!$E:$E, 0))=$D21,"NA") -> TRUE | T21: =IFERROR(INDEX(rawData!$I:$I, MATCH($A21, rawData!$E:$E, 0))=$E21,"NA") -> TRUE | U21: =IFERROR(VALUE(INDEX(rawData!$AI:$AI, MATCH($A21, rawData!$E:$E, 0)))=VALUE($I21),"NA") -> TRUE | V21: =IFERROR(VALUE(INDEX(rawData!$AJ:$AJ, MATCH($A21, rawData!$E:$E, 0)))=VALUE($J21),"NA") -> TRUE | W21: =IFERROR(VALUE(INDEX(rawData!$AK:$AK, MATCH($A21, rawData!$E:$E, 0)))=VALUE($K21),"NA") -> TRUE | X21: =IF(COUNTIF(O21:W21,FALSE)>0,FALSE,TRUE) -> TRUE | Y21: 23
A22: Hypopachus variolosus | B22: 1 | C22: 1 | D22: 1 | E22: NA | F22: 53 | G22: 700 | H22: 700 | I22: 0 | J22: 1 | K22: 0 | L22: =IF( (COUNTIF(B22:E22,"1")+COUNTIF(B22:E22,1))=0, "unknown", MID( IF(OR(B22="1",B22=1)," + fossorial","") & IF(OR(C22="1",C22=1)," + terrestrial","") & IF(OR(D22="1",D22=1)," + aquatic","") & IF(OR(E22="1",E22=1)," + arboreal",""), 4, 999) ) -> fossorial + terrestrial + aquatic | M22: =IF( AND( (COUNTIF(I22:K22,"1")+COUNTIF(I22:K22,1))=0, (COUNTIF(I22:K22,"0")+COUNTIF(I22:K22,0))=0 ), "unknown", IF( (COUNTIF(I22:K22,"1")+COUNTIF(I22:K22,1))>0, MID( IF(OR(I22=1,I22="1")," + direct","") & IF(OR(J22=1,J22="1")," + larval","") & IF(OR(K22=1,K22="1")," + viviparous",""), 4,999), IF( (COUNTIF(I22:K22,"0")+COUNTIF(I22:K22,0))=3, "none", "unknown") ) ) -> larval | N22: =IFERROR(VALUE(INDEX(rawData!$Z:$Z, MATCH($A22, rawData!$E:$E, 0)))=VALUE($F22),"NA") -> TRUE | O22: =IFERROR(VALUE(INDEX(rawData!$AD:$AD, MATCH($A22, rawData!$E:$E, 0)))=VALUE($G22),"NA") -> TRUE | P22: =IFERROR(VALUE(INDEX(rawData!$AE:$AE, MATCH($A22, rawData!$E:$E, 0)))=VALUE($H22),"NA") -> TRUE | Q22: =IFERROR(INDEX(rawData!$F:$F, MATCH($A22, rawData!$E:$E, 0))=$B22,"NA") -> TRUE | R22: =IFERROR(INDEX(rawData!$G:$G, MATCH($A22, rawData!$E:$E, 0))=$C22,"NA") -> TRUE | S22: =IFERROR(INDEX(rawData!$H:$H, MATCH($A22, rawData!$E:$E, 0))=$D22,"NA") -> TRUE | T22: =IFERROR(INDEX(rawData!$I:$I, MATCH($A22, rawData!$E:$E, 0))=$E22,"NA") -> TRUE | U22: =IFERROR(VALUE(INDEX(rawData!$AI:$AI, MATCH($A22, rawData!$E:$E, 0)))=VALUE($I22),"NA") -> TRUE | V22: =IFERROR(VALUE(INDEX(rawData!$AJ:$AJ, MATCH($A22, rawData!$E:$E, 0)))=VALUE($J22),"NA") -> TRUE | W22: =IFERROR(VALUE(INDEX(rawData!$AK:$AK, MATCH($A22, rawData!$E:$E, 0)))=VALUE($K22),"NA") -> TRUE | X22: =IF(COUNTIF(O22:W22,FALSE)>0,FALSE,TRUE) -> TRUE | Y22: 23
A23: Geocrinia victoriana | B23: NA | C23: 1 | D23: 1 | E23: NA | F23: 35 | G23: 126 | H23: 126 | I23: 0 | J23: 1 | K23: 0 | L23: =IF( (COUNTIF(B23:E23,"1")+COUNTIF(B23:E23,1))=0, "unknown", MID( IF(OR(B23="1",B23=1)," + fossorial","") & IF(OR(C23="1",C23=1)," + terrestrial","") & IF(OR(D23="1",D23=1)," + aquatic","") & IF(OR(E23="1",E23=1)," + arboreal",""), 4, 999) ) -> terrestrial + aquatic | M23: =IF( AND( (COUNTIF(I23:K23,"1")+COUNTIF(I23:K23,1))=0, (COUNTIF(I23:K23,"0")+COUNTIF(I23:K23,0))=0 ), "unknown", IF( (COUNTIF(I23:K23,"1")+COUNTIF(I23:K23,1))>0, MID( IF(OR(I23=1,I23="1")," + direct","") & IF(OR(J23=1,J23="1")," + larval","") & IF(OR(K23=1,K23="1")," + viviparous",""), 4,999), IF( (COUNTIF(I23:K23,"0")+COUNTIF(I23:K23,0))=3, "none", "unknown") ) ) -> larval | N23: =IFERROR(VALUE(INDEX(rawData!$Z:$Z, MATCH($A23, rawData!$E:$E, 0)))=VALUE($F23),"NA") -> TRUE | O23: =IFERROR(VALUE(INDEX(rawData!$AD:$AD, MATCH($A23, rawData!$E:$E, 0)))=VALUE($G23),"NA") -> TRUE | P23: =IFERROR(VALUE(INDEX(rawData!$AE:$AE, MATCH($A23, rawData!$E:$E, 0)))=VALUE($H23),"NA") -> TRUE | Q23: =IFERROR(INDEX(rawData!$F:$F, MATCH($A23, rawData!$E:$E, 0))=$B23,"NA") -> TRUE | R23: =IFERROR(INDEX(rawData!$G:$G, MATCH($A23, rawData!$E:$E, 0))=$C23,"NA") -> TRUE | S23: =IFERROR(INDEX(rawData!$H:$H, MATCH($A23, rawData!$E:$E, 0))=$D23,"NA") -> TRUE | T23: =IFERROR(INDEX(rawData!$I:$I, MATCH($A23, rawData!$E:$E, 0))=$E23,"NA") -> TRUE | U23: =IFERROR(VALUE(INDEX(rawData!$AI:$AI, MATCH($A23, rawData!$E:$E, 0)))=VALUE($I23),"NA") -> TRUE | V23: =IFERROR(VALUE(INDEX(rawData!$AJ:$AJ, MATCH($A23, rawData!$E:$E, 0)))=VALUE($J23),"NA") -> TRUE | W23: =IFERROR(VALUE(INDEX(rawData!$AK:$AK, MATCH($A23, rawData!$E:$E, 0)))=VALUE($K23),"NA") -> TRUE | X23: =IF(COUNTIF(O23:W23,FALSE)>0,FALSE,TRUE) -> TRUE | Y23: 23
A24: Eleutherodactylus fowleri | B24: NA | C24: 1 | D24: NA | E24: 1 | F24: 33 | G24: 12 | H24: 12 | I24: 1 | J24: 0 | K24: 0 | L24: =IF( (COUNTIF(B24:E24,"1")+COUNTIF(B24:E24,1))=0, "unknown", MID( IF(OR(B24="1",B24=1)," + fossorial","") & IF(OR(C24="1",C24=1)," + terrestrial","") & IF(OR(D24="1",D24=1)," + aquatic","") & IF(OR(E24="1",E24=1)," + arboreal",""), 4, 999) ) -> terrestrial + arboreal | M24: =IF( AND( (COUNTIF(I24:K24,"1")+COUNTIF(I24:K24,1))=0, (COUNTIF(I24:K24,"0")+COUNTIF(I24:K24,0))=0 ), "unknown", IF( (COUNTIF(I24:K24,"1")+COUNTIF(I24:K24,1))>0, MID( IF(OR(I24=1,I24="1")," + direct","") & IF(OR(J24=1,J24="1")," + larval","") & IF(OR(K24=1,K24="1")," + viviparous",""), 4,999), IF( (COUNTIF(I24:K24,"0")+COUNTIF(I24:K24,0))=3, "none", "unknown") ) ) -> direct | N24: =IFERROR(VALUE(INDEX(rawData!$Z:$Z, MATCH($A24, rawData!$E:$E, 0)))=VALUE($F24),"NA") -> TRUE | O24: =IFERROR(VALUE(INDEX(rawData!$AD:$AD, MATCH($A24, rawData!$E:$E, 0)))=VALUE($G24),"NA") -> TRUE | P24: =IFERROR(VALUE(INDEX(rawData!$AE:$AE, MATCH($A24, rawData!$E:$E, 0)))=VALUE($H24),"NA") -> TRUE | Q24: =IFERROR(INDEX(rawData!$F:$F, MATCH($A24, rawData!$E:$E, 0))=$B24,"NA") -> TRUE | R24: =IFERROR(INDEX(rawData!$G:$G, MATCH($A24, rawData!$E:$E, 0))=$C24,"NA") -> TRUE | S24: =IFERROR(INDEX(rawData!$H:$H, MATCH($A24, rawData!$E:$E, 0))=$D24,"NA") -> TRUE | T24: =IFERROR(INDEX(rawData!$I:$I, MATCH($A24, rawData!$E:$E, 0))=$E24,"NA") -> TRUE | U24: =IFERROR(VALUE(INDEX(rawData!$AI:$AI, MATCH($A24, rawData!$E:$E, 0)))=VALUE($I24),"NA") -> TRUE | V24: =IFERROR(VALUE(INDEX(rawData!$AJ:$AJ, MATCH($A24, rawData!$E:$E, 0)))=VALUE($J24),"NA") -> TRUE | W24: =IFERROR(VALUE(INDEX(rawData!$AK:$AK, MATCH($A24, rawData!$E:$E, 0)))=VALUE($K24),"NA") -> TRUE | X24: =IF(COUNTIF(O24:W24,FALSE)>0,FALSE,TRUE) -> TRUE | Y24: 25
A25: Paradoxophyla palmata | B25: 1 | C25: 1 | D25: 1 | E25: NA | F25: 25.6 | G25: 107 | H25: 408 | I25: 0 | J25: 1 | K25: 0 | L25: =IF( (COUNTIF(B25:E25,"1")+COUNTIF(B25:E25,1))=0, "unknown", MID( IF(OR(B25="1",B25=1)," + fossorial","") & IF(OR(C25="1",C25=1)," + terrestrial","") & IF(OR(D25="1",D25=1)," + aquatic","") & IF(OR(E25="1",E25=1)," + arboreal",""), 4, 999) ) -> fossorial + terrestrial + aquatic | M25: =IF( AND( (COUNTIF(I25:K25,"1")+COUNTIF(I25:K25,1))=0, (COUNTIF(I25:K25,"0")+COUNTIF(I25:K25,0))=0 ), "unknown", IF( (COUNTIF(I25:K25,"1")+COUNTIF(I25:K25,1))>0, MID( IF(OR(I25=1,I25="1")," + direct","") & IF(OR(J25=1,J25="1")," + larval","") & IF(OR(K25=1,K25="1")," + viviparous",""), 4,999), IF( (COUNTIF(I25:K25,"0")+COUNTIF(I25:K25,0))=3, "none", "unknown") ) ) -> larval | N25: =IFERROR(VALUE(INDEX(rawData!$Z:$Z, MATCH($A25, rawData!$E:$E, 0)))=VALUE($F25),"NA") -> TRUE | O25: =IFERROR(VALUE(INDEX(rawData!$AD:$AD, MATCH($A25, rawData!$E:$E, 0)))=VALUE($G25),"NA") -> TRUE | P25: =IFERROR(VALUE(INDEX(rawData!$AE:$AE, MATCH($A25, rawData!$E:$E, 0)))=VALUE($H25),"NA") -> TRUE | Q25: =IFERROR(INDEX(rawData!$F:$F, MATCH($A25, rawData!$E:$E, 0))=$B25,"NA") -> TRUE | R25: =IFERROR(INDEX(rawData!$G:$G, MATCH($A25, rawData!$E:$E, 0))=$C25,"NA") -> TRUE | S25: =IFERROR(INDEX(rawData!$H:$H, MATCH($A25, rawData!$E:$E, 0))=$D25,"NA") -> TRUE | T25: =IFERROR(INDEX(rawData!$I:$I, MATCH($A25, rawData!$E:$E, 0))=$E25,"NA") -> TRUE | U25: =IFERROR(VALUE(INDEX(rawData!$AI:$AI, MATCH($A25, rawData!$E:$E, 0)))=VALUE($I25),"NA") -> TRUE | V25: =IFERROR(VALUE(INDEX(rawData!$AJ:$AJ, MATCH($A25, rawData!$E:$E, 0)))=VALUE($J25),"NA") -> TRUE | W25: =IFERROR(VALUE(INDEX(rawData!$AK:$AK, MATCH($A25, rawData!$E:$E, 0)))=VALUE($K25),"NA") -> TRUE | X25: =IF(COUNTIF(O25:W25,FALSE)>0,FALSE,TRUE) -> TRUE | Y25: 26
A26: Hypsiboas rosenbergi | B26: NA | C26: 1 | D26: 1 | E26: 1 | F26: 95 | G26: 265 | H26: 2500 | I26: 0 | J26: 1 | K26: 0 | L26: =IF( (COUNTIF(B26:E26,"1")+COUNTIF(B26:E26,1))=0, "unknown", MID( IF(OR(B26="1",B26=1)," + fossorial","") & IF(OR(C26="1",C26=1)," + terrestrial","") & IF(OR(D26="1",D26=1)," + aquatic","") & IF(OR(E26="1",E26=1)," + arboreal",""), 4, 999) ) -> terrestrial + aquatic + arboreal | M26: =IF( AND( (COUNTIF(I26:K26,"1")+COUNTIF(I26:K26,1))=0, (COUNTIF(I26:K26,"0")+COUNTIF(I26:K26,0))=0 ), "unknown", IF( (COUNTIF(I26:K26,"1")+COUNTIF(I26:K26,1))>0, MID( IF(OR(I26=1,I26="1")," + direct","") & IF(OR(J26=1,J26="1")," + larval","") & IF(OR(K26=1,K26="1")," + viviparous",""), 4,999), IF( (COUNTIF(I26:K26,"0")+COUNTIF(I26:K26,0))=3, "none", "unknown") ) ) -> larval | N26: =IFERROR(VALUE(INDEX(rawData!$Z:$Z, MATCH($A26, rawData!$E:$E, 0)))=VALUE($F26),"NA") -> TRUE | O26: =IFERROR(VALUE(INDEX(rawData!$AD:$AD, MATCH($A26, rawData!$E:$E, 0)))=VALUE($G26),"NA") -> TRUE | P26: =IFERROR(VALUE(INDEX(rawData!$AE:$AE, MATCH($A26, rawData!$E:$E, 0)))=VALUE($H26),"NA") -> TRUE | Q26: =IFERROR(INDEX(rawData!$F:$F, MATCH($A26, rawData!$E:$E, 0))=$B26,"NA") -> TRUE | R26: =IFERROR(INDEX(rawData!$G:$G, MATCH($A26, rawData!$E:$E, 0))=$C26,"NA") -> TRUE | S26: =IFERROR(INDEX(rawData!$H:$H, MATCH($A26, rawData!$E:$E, 0))=$D26,"NA") -> TRUE | T26: =IFERROR(INDEX(rawData!$I:$I, MATCH($A26, rawData!$E:$E, 0))=$E26,"NA") -> TRUE | U26: =IFERROR(VALUE(INDEX(rawData!$AI:$AI, MATCH($A26, rawData!$E:$E, 0)))=VALUE($I26),"NA") -> TRUE | V26: =IFERROR(VALUE(INDEX(rawData!$AJ:$AJ, MATCH($A26, rawData!$E:$E, 0)))=VALUE($J26),"NA") -> TRUE | W26: =IFERROR(VALUE(INDEX(rawData!$AK:$AK, MATCH($A26, rawData!$E:$E, 0)))=VALUE($K26),"NA") -> TRUE | X26: =IF(COUNTIF(O26:W26,FALSE)>0,FALSE,TRUE) -> TRUE | Y26: 27
A27: Rana ornativentris | B27: NA | C27: 1 | D27: 1 | E27: 1 | F27: 78 | G27: 1000 | H27: 1900 | I27: 0 | J27: 1 | K27: 0 | L27: =IF( (COUNTIF(B27:E27,"1")+COUNTIF(B27:E27,1))=0, "unknown", MID( IF(OR(B27="1",B27=1)," + fossorial","") & IF(OR(C27="1",C27=1)," + terrestrial","") & IF(OR(D27="1",D27=1)," + aquatic","") & IF(OR(E27="1",E27=1)," + arboreal",""), 4, 999) ) -> terrestrial + aquatic + arboreal | M27: =IF( AND( (COUNTIF(I27:K27,"1")+COUNTIF(I27:K27,1))=0, (COUNTIF(I27:K27,"0")+COUNTIF(I27:K27,0))=0 ), "unknown", IF( (COUNTIF(I27:K27,"1")+COUNTIF(I27:K27,1))>0, MID( IF(OR(I27=1,I27="1")," + direct","") & IF(OR(J27=1,J27="1")," + larval","") & IF(OR(K27=1,K27="1")," + viviparous",""), 4,999), IF( (COUNTIF(I27:K27,"0")+COUNTIF(I27:K27,0))=3, "none", "unknown") ) ) -> larval | N27: =IFERROR(VALUE(INDEX(rawData!$Z:$Z, MATCH($A27, rawData!$E:$E, 0)))=VALUE($F27),"NA") -> TRUE | O27: =IFERROR(VALUE(INDEX(rawData!$AD:$AD, MATCH($A27, rawData!$E:$E, 0)))=VALUE($G27),"NA") -> TRUE | P27: =IFERROR(VALUE(INDEX(rawData!$AE:$AE, MATCH($A27, rawData!$E:$E, 0)))=VALUE($H27),"NA") -> TRUE | Q27: =IFERROR(INDEX(rawData!$F:$F, MATCH($A27, rawData!$E:$E, 0))=$B27,"NA") -> TRUE | R27: =IFERROR(INDEX(rawData!$G:$G, MATCH($A27, rawData!$E:$E, 0))=$C27,"NA") -> TRUE | S27: =IFERROR(INDEX(rawData!$H:$H, MATCH($A27, rawData!$E:$E, 0))=$D27,"NA") -> TRUE | T27: =IFERROR(INDEX(rawData!$I:$I, MATCH($A27, rawData!$E:$E, 0))=$E27,"NA") -> TRUE | U27: =IFERROR(VALUE(INDEX(rawData!$AI:$AI, MATCH($A27, rawData!$E:$E, 0)))=VALUE($I27),"NA") -> TRUE | V27: =IFERROR(VALUE(INDEX(rawData!$AJ:$AJ, MATCH($A27, rawData!$E:$E, 0)))=VALUE($J27),"NA") -> TRUE | W27: =IFERROR(VALUE(INDEX(rawData!$AK:$AK, MATCH($A27, rawData!$E:$E, 0)))=VALUE($K27),"NA") -> TRUE | X27: =IF(COUNTIF(O27:W27,FALSE)>0,FALSE,TRUE) -> TRUE | Y27: 30
A28: Ischnocnema juipoca | B28: NA | C28: 1 | D28: NA | E28: NA | F28: 26.26 | G28: 15 | H28: 15 | I28: 1 | J28: 0 | K28: 0 | L28: =IF( (COUNTIF(B28:E28,"1")+COUNTIF(B28:E28,1))=0, "unknown", MID( IF(OR(B28="1",B28=1)," + fossorial","") & IF(OR(C28="1",C28=1)," + terrestrial","") & IF(OR(D28="1",D28=1)," + aquatic","") & IF(OR(E28="1",E28=1)," + arboreal",""), 4, 999) ) -> terrestrial | M28: =IF( AND( (COUNTIF(I28:K28,"1")+COUNTIF(I28:K28,1))=0, (COUNTIF(I28:K28,"0")+COUNTIF(I28:K28,0))=0 ), "unknown", IF( (COUNTIF(I28:K28,"1")+COUNTIF(I28:K28,1))>0, MID( IF(OR(I28=1,I28="1")," + direct","") & IF(OR(J28=1,J28="1")," + larval","") & IF(OR(K28=1,K28="1")," + viviparous",""), 4,999), IF( (COUNTIF(I28:K28,"0")+COUNTIF(I28:K28,0))=3, "none", "unknown") ) ) -> direct | N28: =IFERROR(VALUE(INDEX(rawData!$Z:$Z, MATCH($A28, rawData!$E:$E, 0)))=VALUE($F28),"NA") -> TRUE | O28: =IFERROR(VALUE(INDEX(rawData!$AD:$AD, MATCH($A28, rawData!$E:$E, 0)))=VALUE($G28),"NA") -> TRUE | P28: =IFERROR(VALUE(INDEX(rawData!$AE:$AE, MATCH($A28, rawData!$E:$E, 0)))=VALUE($H28),"NA") -> TRUE | Q28: =IFERROR(INDEX(rawData!$F:$F, MATCH($A28, rawData!$E:$E, 0))=$B28,"NA") -> TRUE | R28: =IFERROR(INDEX(rawData!$G:$G, MATCH($A28, rawData!$E:$E, 0))=$C28,"NA") -> TRUE | S28: =IFERROR(INDEX(rawData!$H:$H, MATCH($A28, rawData!$E:$E, 0))=$D28,"NA") -> TRUE | T28: =IFERROR(INDEX(rawData!$I:$I, MATCH($A28, rawData!$E:$E, 0))=$E28,"NA") -> TRUE | U28: =IFERROR(VALUE(INDEX(rawData!$AI:$AI, MATCH($A28, rawData!$E:$E, 0)))=VALUE($I28),"NA") -> TRUE | V28: =IFERROR(VALUE(INDEX(rawData!$AJ:$AJ, MATCH($A28, rawData!$E:$E, 0)))=VALUE($J28),"NA") -> TRUE | W28: =IFERROR(VALUE(INDEX(rawData!$AK:$AK, MATCH($A28, rawData!$E:$E, 0)))=VALUE($K28),"NA") -> TRUE | X28: =IF(COUNTIF(O28:W28,FALSE)>0,FALSE,TRUE) -> TRUE | Y28: 37
A29: Hyalinobatrachium colymbiphyllum | B29: NA | C29: 1 | D29: 1 | E29: 1 | F29: 29 | G29: 50 | H29: 180 | I29: 0 | J29: 1 | K29: 0 | L29: =IF( (COUNTIF(B29:E29,"1")+COUNTIF(B29:E29,1))=0, "unknown", MID( IF(OR(B29="1",B29=1)," + fossorial","") & IF(OR(C29="1",C29=1)," + terrestrial","") & IF(OR(D29="1",D29=1)," + aquatic","") & IF(OR(E29="1",E29=1)," + arboreal",""), 4, 999) ) -> terrestrial + aquatic + arboreal | M29: =IF( AND( (COUNTIF(I29:K29,"1")+COUNTIF(I29:K29,1))=0, (COUNTIF(I29:K29,"0")+COUNTIF(I29:K29,0))=0 ), "unknown", IF( (COUNTIF(I29:K29,"1")+COUNTIF(I29:K29,1))>0, MID( IF(OR(I29=1,I29="1")," + direct","") & IF(OR(J29=1,J29="1")," + larval","") & IF(OR(K29=1,K29="1")," + viviparous",""), 4,999), IF( (COUNTIF(I29:K29,"0")+COUNTIF(I29:K29,0))=3, "none", "unknown") ) ) -> larval | N29: =IFERROR(VALUE(INDEX(rawData!$Z:$Z, MATCH($A29, rawData!$E:$E, 0)))=VALUE($F29),"NA") -> TRUE | O29: =IFERROR(VALUE(INDEX(rawData!$AD:$AD, MATCH($A29, rawData!$E:$E, 0)))=VALUE($G29),"NA") -> TRUE | P29: =IFERROR(VALUE(INDEX(rawData!$AE:$AE, MATCH($A29, rawData!$E:$E, 0)))=VALUE($H29),"NA") -> TRUE | Q29: =IFERROR(INDEX(rawData!$F:$F, MATCH($A29, rawData!$E:$E, 0))=$B29,"NA") -> TRUE | R29: =IFERROR(INDEX(rawData!$G:$G, MATCH($A29, rawData!$E:$E, 0))=$C29,"NA") -> TRUE | S29: =IFERROR(INDEX(rawData!$H:$H, MATCH($A29, rawData!$E:$E, 0))=$D29,"NA") -> TRUE | T29: =IFERROR(INDEX(rawData!$I:$I, MATCH($A29, rawData!$E:$E, 0))=$E29,"NA") -> TRUE | U29: =IFERROR(VALUE(INDEX(rawData!$AI:$AI, MATCH($A29, rawData!$E:$E, 0)))=VALUE($I29),"NA") -> TRUE | V29: =IFERROR(VALUE(INDEX(rawData!$AJ:$AJ, MATCH($A29, rawData!$E:$E, 0)))=VALUE($J29),"NA") -> TRUE | W29: =IFERROR(VALUE(INDEX(rawData!$AK:$AK, MATCH($A29, rawData!$E:$E, 0)))=VALUE($K29),"NA") -> TRUE | X29: =IF(COUNTIF(O29:W29,FALSE)>0,FALSE,TRUE) -> TRUE | Y29: 37
A30: Hyperolius pickersgilli | B30: NA | C30: 1 | D30: NA | E30: 1 | F30: 30 | G30: 50 | H30: 50 | I30: 0 | J30: 1 | K30: 0 | L30: =IF( (COUNTIF(B30:E30,"1")+COUNTIF(B30:E30,1))=0, "unknown", MID( IF(OR(B30="1",B30=1)," + fossorial","") & IF(OR(C30="1",C30=1)," + terrestrial","") & IF(OR(D30="1",D30=1)," + aquatic","") & IF(OR(E30="1",E30=1)," + arboreal",""), 4, 999) ) -> terrestrial + arboreal | M30: =IF( AND( (COUNTIF(I30:K30,"1")+COUNTIF(I30:K30,1))=0, (COUNTIF(I30:K30,"0")+COUNTIF(I30:K30,0))=0 ), "unknown", IF( (COUNTIF(I30:K30,"1")+COUNTIF(I30:K30,1))>0, MID( IF(OR(I30=1,I30="1")," + direct","") & IF(OR(J30=1,J30="1")," + larval","") & IF(OR(K30=1,K30="1")," + viviparous",""), 4,999), IF( (COUNTIF(I30:K30,"0")+COUNTIF(I30:K30,0))=3, "none", "unknown") ) ) -> larval | N30: =IFERROR(VALUE(INDEX(rawData!$Z:$Z, MATCH($A30, rawData!$E:$E, 0)))=VALUE($F30),"NA") -> TRUE | O30: =IFERROR(VALUE(INDEX(rawData!$AD:$AD, MATCH($A30, rawData!$E:$E, 0)))=VALUE($G30),"NA") -> TRUE | P30: =IFERROR(VALUE(INDEX(rawData!$AE:$AE, MATCH($A30, rawData!$E:$E, 0)))=VALUE($H30),"NA") -> TRUE | Q30: =IFERROR(INDEX(rawData!$F:$F, MATCH($A30, rawData!$E:$E, 0))=$B30,"NA") -> TRUE | R30: =IFERROR(INDEX(rawData!$G:$G, MATCH($A30, rawData!$E:$E, 0))=$C30,"NA") -> TRUE | S30: =IFERROR(INDEX(rawData!$H:$H, MATCH($A30, rawData!$E:$E, 0))=$D30,"NA") -> TRUE | T30: =IFERROR(INDEX(rawData!$I:$I, MATCH($A30, rawData!$E:$E, 0))=$E30,"NA") -> TRUE | U30: =IFERROR(VALUE(INDEX(rawData!$AI:$AI, MATCH($A30, rawData!$E:$E, 0)))=VALUE($I30),"NA") -> TRUE | V30: =IFERROR(VALUE(INDEX(rawData!$AJ:$AJ, MATCH($A30, rawData!$E:$E, 0)))=VALUE($J30),"NA") -> TRUE | W30: =IFERROR(VALUE(INDEX(rawData!$AK:$AK, MATCH($A30, rawData!$E:$E, 0)))=VALUE($K30),"NA") -> TRUE | X30: =IF(COUNTIF(O30:W30,FALSE)>0,FALSE,TRUE) -> TRUE | Y30: 37
A31: Pelophylax bergeri | B31: NA | C31: 1 | D31: 1 | E31: NA | F31: 80 | G31: 3000 | H31: 3000 | I31: 0 | J31: 1 | K31: 0 | L31: =IF( (COUNTIF(B31:E31,"1")+COUNTIF(B31:E31,1))=0, "unknown", MID( IF(OR(B31="1",B31=1)," + fossorial","") & IF(OR(C31="1",C31=1)," + terrestrial","") & IF(OR(D31="1",D31=1)," + aquatic","") & IF(OR(E31="1",E31=1)," + arboreal",""), 4, 999) ) -> terrestrial + aquatic | M31: =IF( AND( (COUNTIF(I31:K31,"1")+COUNTIF(I31:K31,1))=0, (COUNTIF(I31:K31,"0")+COUNTIF(I31:K31,0))=0 ), "unknown", IF( (COUNTIF(I31:K31,"1")+COUNTIF(I31:K31,1))>0, MID( IF(OR(I31=1,I31="1")," + direct","") & IF(OR(J31=1,J31="1")," + larval","") & IF(OR(K31=1,K31="1")," + viviparous",""), 4,999), IF( (COUNTIF(I31:K31,"0")+COUNTIF(I31:K31,0))=3, "none", "unknown") ) ) -> larval | N31: =IFERROR(VALUE(INDEX(rawData!$Z:$Z, MATCH($A31, rawData!$E:$E, 0)))=VALUE($F31),"NA") -> TRUE | O31: =IFERROR(VALUE(INDEX(rawData!$AD:$AD, MATCH($A31, rawData!$E:$E, 0)))=VALUE($G31),"NA") -> TRUE | P31: =IFERROR(VALUE(INDEX(rawData!$AE:$AE, MATCH($A31, rawData!$E:$E, 0)))=VALUE($H31),"NA") -> TRUE | Q31: =IFERROR(INDEX(rawData!$F:$F, MATCH($A31, rawData!$E:$E, 0))=$B31,"NA") -> TRUE | R31: =IFERROR(INDEX(rawData!$G:$G, MATCH($A31, rawData!$E:$E, 0))=$C31,"NA") -> TRUE | S31: =IFERROR(INDEX(rawData!$H:$H, MATCH($A31, rawData!$E:$E, 0))=$D31,"NA") -> TRUE | T31: =IFERROR(INDEX(rawData!$I:$I, MATCH($A31, rawData!$E:$E, 0))=$E31,"NA") -> TRUE | U31: =IFERROR(VALUE(INDEX(rawData!$AI:$AI, MATCH($A31, rawData!$E:$E, 0)))=VALUE($I31),"NA") -> TRUE | V31: =IFERROR(VALUE(INDEX(rawData!$AJ:$AJ, MATCH($A31, rawData!$E:$E, 0)))=VALUE($J31),"NA") -> TRUE | W31: =IFERROR(VALUE(INDEX(rawData!$AK:$AK, MATCH($A31, rawData!$E:$E, 0)))=VALUE($K31),"NA") -> TRUE | X31: =IF(COUNTIF(O31:W31,FALSE)>0,FALSE,TRUE) -> TRUE | Y31: 38
A32: Pristimantis lanthanites | B32: NA | C32: 1 | D32: NA | E32: 1 | F32: 46 | G32: 20 | H32: 332 | I32: 1 | J32: 0 | K32: 0 | L32: =IF( (COUNTIF(B32:E32,"1")+COUNTIF(B32:E32,1))=0, "unknown", MID( IF(OR(B32="1",B32=1)," + fossorial","") & IF(OR(C32="1",C32=1)," + terrestrial","") & IF(OR(D32="1",D32=1)," + aquatic","") & IF(OR(E32="1",E32=1)," + arboreal",""), 4, 999) ) -> terrestrial + arboreal | M32: =IF( AND( (COUNTIF(I32:K32,"1")+COUNTIF(I32:K32,1))=0, (COUNTIF(I32:K32,"0")+COUNTIF(I32:K32,0))=0 ), "unknown", IF( (COUNTIF(I32:K32,"1")+COUNTIF(I32:K32,1))>0, MID( IF(OR(I32=1,I32="1")," + direct","") & IF(OR(J32=1,J32="1")," + larval","") & IF(OR(K32=1,K32="1")," + viviparous",""), 4,999), IF( (COUNTIF(I32:K32,"0")+COUNTIF(I32:K32,0))=3, "none", "unknown") ) ) -> direct | N32: =IFERROR(VALUE(INDEX(rawData!$Z:$Z, MATCH($A32, rawData!$E:$E, 0)))=VALUE($F32),"NA") -> TRUE | O32: =IFERROR(VALUE(INDEX(rawData!$AD:$AD, MATCH($A32, rawData!$E:$E, 0)))=VALUE($G32),"NA") -> TRUE | P32: =IFERROR(VALUE(INDEX(rawData!$AE:$AE, MATCH($A32, rawData!$E:$E, 0)))=VALUE($H32),"NA") -> TRUE | Q32: =IFERROR(INDEX(rawData!$F:$F, MATCH($A32, rawData!$E:$E, 0))=$B32,"NA") -> TRUE | R32: =IFERROR(INDEX(rawData!$G:$G, MATCH($A32, rawData!$E:$E, 0))=$C32,"NA") -> TRUE | S32: =IFERROR(INDEX(rawData!$H:$H, MATCH($A32, rawData!$E:$E, 0))=$D32,"NA") -> TRUE | T32: =IFERROR(INDEX(rawData!$I:$I, MATCH($A32, rawData!$E:$E, 0))=$E32,"NA") -> TRUE | U32: =IFERROR(VALUE(INDEX(rawData!$AI:$AI, MATCH($A32, rawData!$E:$E, 0)))=VALUE($I32),"NA") -> TRUE | V32: =IFERROR(VALUE(INDEX(rawData!$AJ:$AJ, MATCH($A32, rawData!$E:$E, 0)))=VALUE($J32),"NA") -> TRUE | W32: =IFERROR(VALUE(INDEX(rawData!$AK:$AK, MATCH($A32, rawData!$E:$E, 0)))=VALUE($K32),"NA") -> TRUE | X32: =IF(COUNTIF(O32:W32,FALSE)>0,FALSE,TRUE) -> TRUE | Y32: 38
A33: Salamandra algira | B33: NA | C33: 1 | D33: 1 | E33: NA | F33: 226 | G33: 7 | H33: 22 | I33: 0 | J33: 0 | K33: 1 | L33: =IF( (COUNTIF(B33:E33,"1")+COUNTIF(B33:E33,1))=0, "unknown", MID( IF(OR(B33="1",B33=1)," + fossorial","") & IF(OR(C33="1",C33=1)," + terrestrial","") & IF(OR(D33="1",D33=1)," + aquatic","") & IF(OR(E33="1",E33=1)," + arboreal",""), 4, 999) ) -> terrestrial + aquatic | M33: =IF( AND( (COUNTIF(I33:K33,"1")+COUNTIF(I33:K33,1))=0, (COUNTIF(I33:K33,"0")+COUNTIF(I33:K33,0))=0 ), "unknown", IF( (COUNTIF(I33:K33,"1")+COUNTIF(I33:K33,1))>0, MID( IF(OR(I33=1,I33="1")," + direct","") & IF(OR(J33=1,J33="1")," + larval","") & IF(OR(K33=1,K33="1")," + viviparous",""), 4,999), IF( (COUNTIF(I33:K33,"0")+COUNTIF(I33:K33,0))=3, "none", "unknown") ) ) -> viviparous | N33: =IFERROR(VALUE(INDEX(rawData!$Z:$Z, MATCH($A33, rawData!$E:$E, 0)))=VALUE($F33),"NA") -> TRUE | O33: =IFERROR(VALUE(INDEX(rawData!$AD:$AD, MATCH($A33, rawData!$E:$E, 0)))=VALUE($G33),"NA") -> TRUE | P33: =IFERROR(VALUE(INDEX(rawData!$AE:$AE, MATCH($A33, rawData!$E:$E, 0)))=VALUE($H33),"NA") -> TRUE | Q33: =IFERROR(INDEX(rawData!$F:$F, MATCH($A33, rawData!$E:$E, 0))=$B33,"NA") -> TRUE | R33: =IFERROR(INDEX(rawData!$G:$G, MATCH($A33, rawData!$E:$E, 0))=$C33,"NA") -> TRUE | S33: =IFERROR(INDEX(rawData!$H:$H, MATCH($A33, rawData!$E:$E, 0))=$D33,"NA") -> TRUE | T33: =IFERROR(INDEX(rawData!$I:$I, MATCH($A33, rawData!$E:$E, 0))=$E33,"NA") -> TRUE | U33: =IFERROR(VALUE(INDEX(rawData!$AI:$AI, MATCH($A33, rawData!$E:$E, 0)))=VALUE($I33),"NA") -> TRUE | V33: =IFERROR(VALUE(INDEX(rawData!$AJ:$AJ, MATCH($A33, rawData!$E:$E, 0)))=VALUE($J33),"NA") -> TRUE | W33: =IFERROR(VALUE(INDEX(rawData!$AK:$AK, MATCH($A33, rawData!$E:$E, 0)))=VALUE($K33),"NA") -> TRUE | X33: =IF(COUNTIF(O33:W33,FALSE)>0,FALSE,TRUE) -> TRUE | Y33: 39
A34: Eleutherodactylus guantanamera | B34: NA | C34: 1 | D34: NA | E34: 1 | F34: 37.3 | G34: 5 | H34: 13 | I34: 1 | J34: 0 | K34: 0 | L34: =IF( (COUNTIF(B34:E34,"1")+COUNTIF(B34:E34,1))=0, "unknown", MID( IF(OR(B34="1",B34=1)," + fossorial","") & IF(OR(C34="1",C34=1)," + terrestrial","") & IF(OR(D34="1",D34=1)," + aquatic","") & IF(OR(E34="1",E34=1)," + arboreal",""), 4, 999) ) -> terrestrial + arboreal | M34: =IF( AND( (COUNTIF(I34:K34,"1")+COUNTIF(I34:K34,1))=0, (COUNTIF(I34:K34,"0")+COUNTIF(I34:K34,0))=0 ), "unknown", IF( (COUNTIF(I34:K34,"1")+COUNTIF(I34:K34,1))>0, MID( IF(OR(I34=1,I34="1")," + direct","") & IF(OR(J34=1,J34="1")," + larval","") & IF(OR(K34=1,K34="1")," + viviparous",""), 4,999), IF( (COUNTIF(I34:K34,"0")+COUNTIF(I34:K34,0))=3, "none", "unknown") ) ) -> direct | N34: =IFERROR(VALUE(INDEX(rawData!$Z:$Z, MATCH($A34, rawData!$E:$E, 0)))=VALUE($F34),"NA") -> TRUE | O34: =IFERROR(VALUE(INDEX(rawData!$AD:$AD, MATCH($A34, rawData!$E:$E, 0)))=VALUE($G34),"NA") -> TRUE | P34: =IFERROR(VALUE(INDEX(rawData!$AE:$AE, MATCH($A34, rawData!$E:$E, 0)))=VALUE($H34),"NA") -> TRUE | Q34: =IFERROR(INDEX(rawData!$F:$F, MATCH($A34, rawData!$E:$E, 0))=$B34,"NA") -> TRUE | R34: =IFERROR(INDEX(rawData!$G:$G, MATCH($A34, rawData!$E:$E, 0))=$C34,"NA") -> TRUE | S34: =IFERROR(INDEX(rawData!$H:$H, MATCH($A34, rawData!$E:$E, 0))=$D34,"NA") -> TRUE | T34: =IFERROR(INDEX(rawData!$I:$I, MATCH($A34, rawData!$E:$E, 0))=$E34,"NA") -> TRUE | U34: =IFERROR(VALUE(INDEX(rawData!$AI:$AI, MATCH($A34, rawData!$E:$E, 0)))=VALUE($I34),"NA") -> TRUE | V34: =IFERROR(VALUE(INDEX(rawData!$AJ:$AJ, MATCH($A34, rawData!$E:$E, 0)))=VALUE($J34),"NA") -> TRUE | W34: =IFERROR(VALUE(INDEX(rawData!$AK:$AK, MATCH($A34, rawData!$E:$E, 0)))=VALUE($K34),"NA") -> TRUE | X34: =IF(COUNTIF(O34:W34,FALSE)>0,FALSE,TRUE) -> TRUE | Y34: 40
